Workbook

Sheet Indice cap.4
A1: Capítulo 4
A2: PRODUCCIÓN, ÍNDICES DE PRECIOS Y POBLACIÓN
A4: PRODUCCIÓN
A6: 4.1 Oferta y Utilización Final de Bienes y Servicios / Miles de dólares de 2007
A7: 4.2 Oferta y Utilización Final de Bienes y Servicios/ Miles de dólares
A8: 4.3 Oferta y Utilización Final de Bienes y Servicios / Tasas de variación a Precios de 2007
A9: 4.4 Oferta y Utilización Final de Bienes y Servicios / Deflactores implícitos
A10: 4.5 Oferta y Utilización Final de Bienes y Servicios / Participación en el PIB - A precios de 2007
A11: 4.6 Oferta y Utilización Final de Bienes y Servicios / Contribución al crecimiento del PIB - A precios de 2007
A13: ÍNDICE DE PRECIOS
A15: 4.7 Indice Ponderado de Precios al Consumidor por Ciudades y por Categorías de Bienes y Servicios (1940-2014)
A16: 4.7.a Indice Ponderado de Precios al Consumidor por Ciudades y por Categorías de Bienes y Servicios (2015-2016)
... A49: Notas metodológicas de este capítulo

Sheet 4.1
A1: 4.1 OFERTA Y UTILIZACIÓN FINAL DE BIENES Y SERVICIOS
A2: Miles de dólares de 2007
A4: AÑOS | B4: Producto interno bruto (PIB) | C4: Importaciones de bienes y servicios | D4: Total oferta final | E4: Gasto de consumo final total | F4: Gobierno general | G4: Hogares residentes (*) | H4: Formación bruta de capital fijo | I4: Variación de existencias | J4: Exportaciones de bienes y servicios | K4: Total demanda final
A6: 1965 | B6: 10315274 | C6: 1663211 | D6: 11978485 | E6: 7756361 | F6: 1169835 | G6: 6586526 | H6: 2900959 | I6: 433141 | J6: 888024 | K6: 11978485
A7: 1966 | B7: 10280251 | C7: 1717049 | D7: 11997300 | E7: 7816797 | F7: 1183997 | G7: 6632800 | H7: 2932210 | I7: 326686 | J7: 921607 | K7: 11997300
A8: 1967 | B8: 10755309 | C8: 2069823 | D8: 12825132 | E8: 8108626 | F8: 1255248 | G8: 6853378 | H8: 3451557 | I8: 276198 | J8: 988751 | K8: 12825132
A9: 1968 | B9: 10960675 | C9: 2328028 | D9: 13288703 | E9: 8515648 | F9: 1336105 | G9: 7179543 | H9: 3654993 | I9: 103067 | J9: 1014995 | K9: 13288703
A10: 1969 | B10: 11472455 | C10: 2328566 | D10: 13801021 | E10: 9019510 | F10: 1448806 | G10: 7570704 | H10: 3764536 | I10: 125797 | J10: 891178 | K10: 13801021
A11: 1970 | B11: 12260834 | C11: 2403425 | D11: 14664259 | E11: 9723720 | F11: 1498394 | G11: 8225326 | H11: 3755199 | I11: 292490 | J11: 892850 | K11: 14664259
A12: 1971 | B12: 13032360 | C12: 2893429 | D12: 15925789 | E12: 10166640 | F12: 1514325 | G12: 8652315 | H12: 4696063 | I12: 76266 | J12: 986820 | K12: 15925789
A13: 1972 | B13: 13686277 | C13: 2727824 | D13: 16414101 | E13: 10012395 | F13: 1536926 | G13: 8475469 | H13: 4485935 | I13: 122234 | J13: 1793537 | K13: 16414101
A14: 1973 | B14: 15595606 | C14: 3226114 | D14: 18821720 | E14: 10634999 | F14: 1744447 | G14: 8890552 | H14: 4518591 | I14: -109630 | J14: 3777760 | K14: 18821720
A15: 1974 | B15: 17343641 | C15: 4740177 | D15: 22083818 | E15: 13216565 | F15: 2921326 | G15: 10295239 | H15: 4749379 | I15: -518379 | J15: 4636253 | K15: 22083818
A16: 1975 | B16: 19246612 | C16: 5001366 | D16: 24247978 | E16: 14810253 | F16: 3064627 | G16: 11745626 | H16: 5825874 | I16: -131068 | J16: 3742919 | K16: 24247978
A17: 1976 | B17: 20670320 | C17: 5100825 | D17: 25771145 | E17: 15979022 | F17: 3373336 | G17: 12605686 | H17: 6096519 | I17: -145812 | J17: 3841416 | K17: 25771145
... A54: 2013 | B54: 67546128 | C54: 20691563 | D54: 88237691 | E54: 51552041 | F54: 9609763 | G54: 41942278 | H54: 18214094 | I54: 261276 | J54: 18210280 | K54: 88237691
A55: 2014 sd | B55: 70243048 | C55: 21584147 | D55: 91827195 | E55: 53487685 | F55: 10111927 | G55: 43375758 | H55: 18904840 | I55: 460212 | J55: 18974458 | K55: 91827195
A56: 2015 p | B56: 70353852 | C56: 19731906 | D56: 90085758 | E56: 53485516 | F56: 10172307 | G56: 43313209 | H56: 17797927 | I56: -101688 | J56: 18904003 | K56: 90085758
A57: 2016 prel | B57: 69321410 | C57: 18462598 | D57: 87784008 | E57: 52341737 | F57: 9831775 | G57: 42509962 | H57: 16367027 | I57: 230738 | J57: 18844506 | K57: 87784008
A59: (*) Incluye Instituciones sin fines de lucro que sirven a los hogares
A60: sd: semidefinitivo
A61: p: provisional
A62: prel: preliminar por sumatoria de trimestres
A67: regresar al índice

Sheet 4.2
A1: 4.2 OFERTA Y UTILIZACIÓN FINAL DE BIENES Y SERVICIOS
A2: Miles de dólares
A4: AÑOS | B4: Producto interno bruto (PIB) | C4: Importaciones de bienes y servicios | D4: Total oferta final | E4: Gasto de consumo final total | F4: Gobierno general | G4: Hogares residentes (*) | H4: Formación bruta de capital fijo | I4: Variación de existencias | J4: Exportaciones de bienes y servicios | K4: Total demanda final
A6: 1965 | B6: 2385904 | C6: 245521 | D6: 2631425 | E6: 1835856 | F6: 225077 | G6: 1610779 | H6: 254420 | I6: 326903 | J6: 214246 | K6: 2631425
A7: 1966 | B7: 2428145 | C7: 269873 | D7: 2698018 | E7: 1899932 | F7: 222215 | G7: 1677717 | H7: 273737 | I7: 269741 | J7: 254608 | K7: 2698018
A8: 1967 | B8: 2552372 | C8: 307091 | D8: 2859463 | E8: 2016892 | F8: 190970 | G8: 1825922 | H8: 342052 | I8: 242546 | J8: 257973 | K8: 2859463
A9: 1968 | B9: 2580943 | C9: 359221 | D9: 2940164 | E9: 2181370 | F9: 185762 | G9: 1995608 | H9: 384334 | I9: 89468 | J9: 284992 | K9: 2940164
A10: 1969 | B10: 3110675 | C10: 376465 | D10: 3487140 | E10: 2523236 | F10: 256195 | G10: 2267041 | H10: 442828 | I10: 256577 | J10: 264499 | K10: 3487140
A11: 1970 | B11: 2861132 | C11: 372234 | D11: 3233366 | E11: 2403605 | F11: 277339 | G11: 2126266 | H11: 450556 | I11: 109079 | J11: 270126 | K11: 3233366
A12: 1971 | B12: 2752900 | C12: 459462 | D12: 3212362 | E12: 2304476 | F12: 234341 | G12: 2070135 | H12: 512330 | I12: 104288 | J12: 291268 | K12: 3212362
A13: 1972 | B13: 3184460 | C13: 495186 | D13: 3679646 | E13: 2544022 | F13: 293838 | G13: 2250184 | H13: 633048 | I13: 107451 | J13: 395125 | K13: 3679646
A14: 1973 | B14: 3889890 | C14: 648040 | D14: 4537930 | E14: 3044078 | F14: 420376 | G14: 2623702 | H14: 915277 | I14: -116861 | J14: 695436 | K14: 4537930
A15: 1974 | B15: 6596096 | C15: 1236921 | D15: 7833017 | E15: 4713377 | F15: 1057872 | G15: 3655505 | H15: 966016 | I15: 659473 | J15: 1494151 | K15: 7833017
A16: 1975 | B16: 7727971 | C16: 1494138 | D16: 9222109 | E16: 6390137 | F16: 1618152 | G16: 4771985 | H16: 1430749 | I16: 159269 | J16: 1241954 | K16: 9222109
A17: 1976 | B17: 9087566 | C17: 1633787 | D17: 10721353 | E17: 7350648 | F17: 1834862 | G17: 5515786 | H17: 1719679 | I17: 193777 | J17: 1457249 | K17: 10721353
... A54: 2013 | B54: 95129659 | C54: 29459627 | D54: 124589286 | E54: 70265165 | F54: 13323278 | G54: 56941887 | H54: 26211660 | I54: 868955 | J54: 27243506 | K54: 124589286
A55: 2014 sd | B55: 102292260 | C55: 30173593 | D55: 132465853 | E55: 74999440 | F55: 14442181 | G55: 60557259 | H55: 27702468 | I55: 1130848 | J55: 28633097 | K55: 132465853
A56: 2015 p | B56: 100176808 | C56: 23702545 | D56: 123879353 | E56: 76267509 | F56: 14402697 | G56: 61864812 | H56: 26359701 | I56: 541993 | J56: 20710150 | K56: 123879353
A57: 2016 prel | B57: 97802211 | C57: 19219016 | D57: 117021227 | E57: 75154200 | F57: 14025347 | G57: 61128853 | H57: 23026212 | I57: -44661 | J57: 18885476 | K57: 117021227
A59: (*) Incluye Instituciones sin fines de lucro que sirven a los hogares
A60: sd: semidefinitivo
A61: p: provisional
A62: prel: preliminar por sumatoria de trimestres
A67: regresar al índice

Sheet 4.3
A1: 4.3 OFERTA Y UTILIZACIÓN FINAL DE BIENES Y SERVICIOS
A2: Tasas de variación
A3: A precios de 2007
A5: AÑOS | B5: Producto interno bruto (PIB) | C5: Importaciones de bienes y servicios | D5: Total oferta final | E5: Gasto de consumo final total | F5: Gobierno general | G5: Hogares residentes (*) | H5: Formación bruta de capital fijo | I5: Exportaciones de bienes y servicios | J5: Total demanda final
A7: 1966 | B7: -0.33952564 | C7: 3.2369916 | D7: 0.15707329 | E7: 0.77917982 | F7: 1.2105981 | G7: 0.70255549 | H7: 1.0772644 | I7: 3.7817672 | J7: 0.15707329
A8: 1967 | B8: 4.6210739 | C8: 20.545366 | D8: 6.9001525 | E8: 3.7333578 | F8: 6.0178362 | G8: 3.3255639 | H8: 17.711794 | I8: 7.2855349 | J8: 6.9001525
A9: 1968 | B9: 1.9094384 | C9: 12.474738 | D9: 3.6145515 | E9: 5.0196174 | F9: 6.4415159 | G9: 4.7591859 | H9: 5.8940356 | I9: 2.6542577 | J9: 3.6145515
A10: 1969 | B10: 4.669238 | C10: 0.023109688 | D10: 3.8552897 | E10: 5.9168956 | F10: 8.4350407 | G10: 5.4482716 | H10: 2.9970782 | I10: -12.198779 | J10: 3.8552897
A11: 1970 | B11: 6.8719293 | C11: 3.2148112 | D11: 6.2548851 | E11: 7.8076303 | F11: 3.4226805 | G11: 8.6467784 | H11: -0.24802525 | I11: 0.18761684 | J11: 6.2548851
A12: 1971 | B12: 6.2926062 | C12: 20.387738 | D12: 8.6027531 | E12: 4.5550468 | F12: 1.063205 | G12: 5.1911499 | H12: 25.05497 | I12: 10.524724 | J12: 8.6027531
A13: 1972 | B13: 5.0176407 | C13: -5.7234859 | D13: 3.0661715 | E13: -1.5171679 | F13: 1.4924801 | G13: -2.0439154 | H13: -4.4745567 | I13: 81.749154 | J13: 3.0661715
A14: 1973 | B14: 13.950682 | C14: 18.266941 | D14: 14.667992 | E14: 6.2183324 | F14: 13.502342 | G14: 4.8974635 | H14: 0.72796418 | I14: 110.63184 | J14: 14.667992
A15: 1974 | B15: 11.20851 | C15: 46.931479 | D15: 17.331562 | E15: 24.274248 | F15: 67.464302 | G15: 15.799773 | H15: 5.1075213 | I15: 22.724922 | J15: 17.331562
A16: 1975 | B16: 10.972154 | C16: 5.5101107 | D16: 9.7997547 | E16: 12.058262 | F16: 4.9053409 | G16: 14.087939 | H16: 22.666016 | I16: -19.268448 | J16: 9.7997547
A17: 1976 | B17: 7.3971876 | C17: 1.9886367 | D17: 6.2816248 | E17: 7.8916208 | F17: 10.073298 | G17: 7.3223854 | H17: 4.6455691 | I17: 2.6315557 | J17: 6.2816248
A18: 1977 | B18: 1.6048421 | C18: 17.304926 | D18: 4.7123246 | E18: 3.846537 | F18: 4.329542 | G18: 3.7172828 | H18: 9.7791051 | I18: 1.476669 | J18: 4.7123246
... A54: 2013 | B54: 4.9465113 | C54: 6.9659671 | D54: 5.4131952 | E54: 5.0496605 | F54: 10.303736 | G54: 3.9155708 | H54: 10.414091 | I54: 2.5583551 | J54: 5.4131952
A55: 2014 sd | B55: 3.9927085 | C55: 4.3137582 | D55: 4.067994 | E55: 3.7547379 | F55: 5.2255607 | G55: 3.4177447 | H55: 3.7923709 | I55: 4.1964099 | J55: 4.067994
A56: 2015 p | B56: 0.15774372 | C56: -8.5814881 | D56: -1.8964284 | E56: -0.004055139 | F56: 0.59711665 | G56: -0.14420267 | H56: -5.8551831 | I56: -0.37131495 | J56: -1.8964284
A57: 2016 prel | B57: -1.4674989 | C57: -6.4327693 | D57: -2.5550654 | E57: -2.1384836 | F57: -3.3476379 | G57: -1.8545082 | H57: -8.0397004 | I57: -0.31473228 | J57: -2.5550654
A59: (*) Incluye Instituciones sin fines de lucro que sirven a los hogares
A60: sd: semidefinitivo
A61: p: provisional
A62: prel: preliminar por sumatoria de trimestres
A67: regresar al índice

Sheet 4.4
A1: 4.4 OFERTA Y UTILIZACIÓN FINAL DE BIENES Y SERVICIOS
A2: Deflactores implícitos
A3: 2007=100
A5: AÑOS | B5: Producto interno bruto (PIB) | C5: Importaciones de bienes y servicios | D5: Total oferta final | E5: Gasto de consumo final total | F5: Gobierno general | G5: Hogares residentes (*) | H5: Formación bruta de capital fijo | I5: Exportaciones de bienes y servicios | J5: Total demanda final
A7: 1965 | B7: 23.129817 | C7: 14.761867 | D7: 21.967928 | E7: 23.669038 | F7: 19.240064 | G7: 24.455669 | H7: 8.7702032 | I7: 24.12615 | J7: 21.967928
A8: 1966 | B8: 23.619511 | C8: 15.717257 | D8: 22.488543 | E8: 24.305761 | F8: 18.768206 | G8: 25.29425 | H8: 9.3355183 | I8: 27.626526 | J8: 22.488543
A9: 1967 | B9: 23.731275 | C9: 14.836583 | D9: 22.295778 | E9: 24.873413 | F9: 15.213727 | G9: 26.642657 | H9: 9.9100783 | I9: 26.090795 | J9: 22.295778
A10: 1968 | B10: 23.5473 | C10: 15.43027 | D10: 22.125289 | E10: 25.616019 | F10: 13.903249 | G10: 27.795752 | H10: 10.515314 | I10: 28.078168 | J10: 22.125289
A11: 1969 | B11: 27.114292 | C11: 16.167246 | D11: 25.267261 | E11: 27.975311 | F11: 17.683182 | G11: 29.944917 | H11: 11.76315 | I11: 29.679705 | J11: 25.267261
A12: 1970 | B12: 23.335541 | C12: 15.487648 | D12: 22.049297 | E12: 24.718986 | F12: 18.509084 | G12: 25.850234 | H12: 11.998192 | I12: 30.254354 | J12: 22.049297
A13: 1971 | B13: 21.123572 | C13: 15.879498 | D13: 20.170819 | E13: 22.667037 | F13: 15.474948 | G13: 23.925793 | H13: 10.909777 | I13: 29.515818 | J13: 20.170819
A14: 1972 | B14: 23.26754 | C14: 18.153151 | D14: 22.417591 | E14: 25.408726 | F14: 19.118552 | G14: 26.549374 | H14: 14.111841 | I14: 22.030491 | J14: 22.417591
A15: 1973 | B15: 24.942218 | C15: 20.087325 | D15: 24.110071 | E15: 28.623209 | F15: 24.097952 | G15: 29.511126 | H15: 20.255805 | I15: 18.408687 | J15: 24.110071
A16: 1974 | B16: 38.031784 | C16: 26.094405 | D16: 35.469487 | E16: 35.662648 | F16: 36.212049 | G16: 35.506752 | H16: 20.339838 | I16: 32.227555 | J16: 35.469487
A17: 1975 | B17: 40.152371 | C17: 29.874598 | D17: 38.032487 | E17: 43.146711 | F17: 52.800944 | G17: 40.627762 | H17: 24.55853 | I17: 33.181429 | J17: 38.032487
A18: 1976 | B18: 43.964322 | C18: 32.029858 | D18: 41.60216 | E18: 46.001864 | F18: 54.393099 | G18: 43.756333 | H18: 28.207556 | I18: 37.935204 | J18: 41.60216
... A47: 2005 | B47: 86.81798 | C47: 88.848246 | D47: 87.260001 | E47: 92.360607 | F47: 87.548191 | G47: 93.161762 | H47: 87.12879 | I47: 75.409744 | J47: 87.260001
A48: 2006 | B48: =+('[1]4.2'!B47/'[1]4.1'!B47)*100 -> 93.764209 | C48: =+('[1]4.2'!C47/'[1]4.1'!C47)*100 -> 94.130807 | D48: =+('[1]4.2'!D47/'[1]4.1'!D47)*100 -> 93.847199 | E48: =+('[1]4.2'!E47/'[1]4.1'!E47)*100 -> 96.544254 | F48: =+('[1]4.2'!F47/'[1]4.1'!F47)*100 -> 94.078209 | G48: =+('[1]4.2'!G47/'[1]4.1'!G47)*100 -> 96.952602 | H48: =+('[1]4.2'!H47/'[1]4.1'!H47)*100 -> 95.554003 | I48: =+('[1]4.2'!J47/'[1]4.1'!J47)*100 -> 87.17594 | J48: =+('[1]4.2'!K47/'[1]4.1'!K47)*100 -> 93.847199
A49: 2007 | B49: =+('[1]4.2'!B48/'[1]4.1'!B48)*100 -> 100 | C49: =+('[1]4.2'!C48/'[1]4.1'!C48)*100 -> 100 | D49: =+('[1]4.2'!D48/'[1]4.1'!D48)*100 -> 100 | E49: =+('[1]4.2'!E48/'[1]4.1'!E48)*100 -> 100 | F49: =+('[1]4.2'!F48/'[1]4.1'!F48)*100 -> 100 | G49: =+('[1]4.2'!G48/'[1]4.1'!G48)*100 -> 100 | H49: =+('[1]4.2'!H48/'[1]4.1'!H48)*100 -> 100 | I49: =+('[1]4.2'!J48/'[1]4.1'!J48)*100 -> 100 | J49: =+('[1]4.2'!K48/'[1]4.1'!K48)*100 -> 100
A50: 2008 | B50: =+('[1]4.2'!B49/'[1]4.1'!B49)*100 -> 113.84732 | C50: =+('[1]4.2'!C49/'[1]4.1'!C49)*100 -> 116.98278 | D50: =+('[1]4.2'!D49/'[1]4.1'!D49)*100 -> 114.62502 | E50: =+('[1]4.2'!E49/'[1]4.1'!E49)*100 -> 109.98355 | F50: =+('[1]4.2'!F49/'[1]4.1'!F49)*100 -> 118.01611 | G50: =+('[1]4.2'!G49/'[1]4.1'!G49)*100 -> 108.56242 | H50: =+('[1]4.2'!H49/'[1]4.1'!H49)*100 -> 112.47169 | I50: =+('[1]4.2'!J49/'[1]4.1'!J49)*100 -> 125.79433 | J50: =+('[1]4.2'!K49/'[1]4.1'!K49)*100 -> 114.62502
A51: 2009 | B51: =+('[1]4.2'!B50/'[1]4.1'!B50)*100 -> 114.59363 | C51: =+('[1]4.2'!C50/'[1]4.1'!C50)*100 -> 104.1608 | D51: =+('[1]4.2'!D50/'[1]4.1'!D50)*100 -> 112.2142 | E51: =+('[1]4.2'!E50/'[1]4.1'!E50)*100 -> 114.28321 | F51: =+('[1]4.2'!F50/'[1]4.1'!F50)*100 -> 124.18176 | G51: =+('[1]4.2'!G50/'[1]4.1'!G50)*100 -> 112.30905 | H51: =+('[1]4.2'!H50/'[1]4.1'!H50)*100 -> 120.38582 | I51: =+('[1]4.2'!J50/'[1]4.1'!J50)*100 -> 98.842523 | J51: =+('[1]4.2'!K50/'[1]4.1'!K50)*100 -> 112.2142
A52: 2010 | B52: =+('[1]4.2'!B51/'[1]4.1'!B51)*100 -> 123.14814 | C52: =+('[1]4.2'!C51/'[1]4.1'!C51)*100 -> 121.78786 | D52: =+('[1]4.2'!D51/'[1]4.1'!D51)*100 -> 122.81239 | E52: =+('[1]4.2'!E51/'[1]4.1'!E51)*100 -> 119.44358 | F52: =+('[1]4.2'!F51/'[1]4.1'!F51)*100 -> 127.27609 | G52: =+('[1]4.2'!G51/'[1]4.1'!G51)*100 -> 117.92968 | H52: =+('[1]4.2'!H51/'[1]4.1'!H51)*100 -> 131.2467 | I52: =+('[1]4.2'!J51/'[1]4.1'!J51)*100 -> 121.7778 | J52: =+('[1]4.2'!K51/'[1]4.1'!K51)*100 -> 122.81239
A53: 2011 | B53: =+('[1]4.2'!B52/'[1]4.1'!B52)*100 -> 130.12159 | C53: =+('[1]4.2'!C52/'[1]4.1'!C52)*100 -> 137.89614 | D53: =+('[1]4.2'!D52/'[1]4.1'!D52)*100 -> 131.98338 | E53: =+('[1]4.2'!E52/'[1]4.1'!E52)*100 -> 124.79593 | F53: =+('[1]4.2'!F52/'[1]4.1'!F52)*100 -> 128.69937 | G53: =+('[1]4.2'!G52/'[1]4.1'!G52)*100 -> 124.01584 | H53: =+('[1]4.2'!H52/'[1]4.1'!H52)*100 -> 137.19639 | I53: =+('[1]4.2'!J52/'[1]4.1'!J52)*100 -> 146.54499 | J53: =+('[1]4.2'!K52/'[1]4.1'!K52)*100 -> 131.98338
A54: 2012 | B54: =+('[1]4.2'!B53/'[1]4.1'!B53)*100 -> 136.60848 | C54: =+('[1]4.2'!C53/'[1]4.1'!C53)*100 -> 143.56919 | D54: =+('[1]4.2'!D53/'[1]4.1'!D53)*100 -> 138.21706 | E54: =+('[1]4.2'!E53/'[1]4.1'!E53)*100 -> 131.91315 | F54: =+('[1]4.2'!F53/'[1]4.1'!F53)*100 -> 134.60317 | G54: =+('[1]4.2'!G53/'[1]4.1'!G53)*100 -> 131.33251 | H54: =+('[1]4.2'!H53/'[1]4.1'!H53)*100 -> 143.71724 | I54: =+('[1]4.2'!J53/'[1]4.1'!J53)*100 -> 149.3706 | J54: =+('[1]4.2'!K53/'[1]4.1'!K53)*100 -> 138.21706
A55: 2013 | B55: =+('[1]4.2'!B54/'[1]4.1'!B54)*100 -> 140.83658 | C55: =+('[1]4.2'!C54/'[1]4.1'!C54)*100 -> 142.37507 | D55: =+('[1]4.2'!D54/'[1]4.1'!D54)*100 -> 141.19736 | E55: =+('[1]4.2'!E54/'[1]4.1'!E54)*100 -> 136.29948 | F55: =+('[1]4.2'!F54/'[1]4.1'!F54)*100 -> 138.64315 | G55: =+('[1]4.2'!G54/'[1]4.1'!G54)*100 -> 135.7625 | H55: =+('[1]4.2'!H54/'[1]4.1'!H54)*100 -> 143.90867 | I55: =+('[1]4.2'!J54/'[1]4.1'!J54)*100 -> 149.60509 | J55: =+('[1]4.2'!K54/'[1]4.1'!K54)*100 -> 141.19736
A56: 2014 sd | B56: =+('[1]4.2'!B55/'[1]4.1'!B55)*100 -> 145.62617 | C56: =+('[1]4.2'!C55/'[1]4.1'!C55)*100 -> 139.79516 | D56: =+('[1]4.2'!D55/'[1]4.1'!D55)*100 -> 144.25558 | E56: =+('[1]4.2'!E55/'[1]4.1'!E55)*100 -> 140.21815 | F56: =+('[1]4.2'!F55/'[1]4.1'!F55)*100 -> 142.82323 | G56: =+('[1]4.2'!G55/'[1]4.1'!G55)*100 -> 139.61084 | H56: =+('[1]4.2'!H55/'[1]4.1'!H55)*100 -> 146.53638 | I56: =+('[1]4.2'!J55/'[1]4.1'!J55)*100 -> 150.90337 | J56: =+('[1]4.2'!K55/'[1]4.1'!K55)*100 -> 144.25558
A57: 2015 p | B57: =+('[1]4.2'!B56/'[1]4.1'!B56)*100 -> 142.38994 | C57: =+('[1]4.2'!C56/'[1]4.1'!C56)*100 -> 120.12294 | D57: =+('[1]4.2'!D56/'[1]4.1'!D56)*100 -> 137.51269 | E57: =+('[1]4.2'!E56/'[1]4.1'!E56)*100 -> 142.5947 | F57: =+('[1]4.2'!F56/'[1]4.1'!F56)*100 -> 141.58732 | G57: =+('[1]4.2'!G56/'[1]4.1'!G56)*100 -> 142.83128 | H57: =+('[1]4.2'!H56/'[1]4.1'!H56)*100 -> 148.10546 | I57: =+('[1]4.2'!J56/'[1]4.1'!J56)*100 -> 109.55431 | J57: =+('[1]4.2'!K56/'[1]4.1'!K56)*100 -> 137.51269
A58: 2016 prel | B58: =+('[1]4.2'!B57/'[1]4.1'!B57)*100 -> 141.08514 | C58: =+('[1]4.2'!C57/'[1]4.1'!C57)*100 -> 104.09703 | D58: =+('[1]4.2'!D57/'[1]4.1'!D57)*100 -> 133.30586 | E58: =+('[1]4.2'!E57/'[1]4.1'!E57)*100 -> 143.58369 | F58: =+('[1]4.2'!F57/'[1]4.1'!F57)*100 -> 142.65325 | G58: =+('[1]4.2'!G57/'[1]4.1'!G57)*100 -> 143.79889 | H58: =+('[1]4.2'!H57/'[1]4.1'!H57)*100 -> 140.68659 | I58: =+('[1]4.2'!J57/'[1]4.1'!J57)*100 -> 100.21741 | J58: =+('[1]4.2'!K57/'[1]4.1'!K57)*100 -> 133.30586
A60: (*) Incluye Instituciones sin fines de lucro que sirven a los hogares
A61: sd: semidefinitivo
A62: p: provisional
A63: prel: preliminar por sumatoria de trimestres
A68: regresar al índice

Sheet 4.5
A1: 4.5 OFERTA Y UTILIZACIÓN FINAL DE BIENES Y SERVICIOS
A2: Participación en el PIB
A3: A precios de 2007
A5: AÑOS | B5: Producto interno bruto (PIB) | C5: Importaciones de bienes y servicios | D5: Gasto de consumo final total | E5: Gobierno general | F5: Hogares residentes(*) | G5: Formación bruta de capital fijo | H5: Variación de existencias | I5: Exportaciones de bienes y servicios
A7: 1965 | B7: 100 | C7: 16.123769 | D7: 75.192971 | E7: 11.340804 | F7: 63.852167 | G7: 28.122947 | H7: 4.1990256 | I7: 8.6088261
A8: 1966 | B8: 100 | C8: 16.702403 | D8: 76.037025 | E8: 11.517199 | F8: 64.519825 | G8: 28.522747 | H8: 3.1778018 | I8: 8.9648297
A9: 1967 | B9: 100 | C9: 19.244663 | D9: 75.391846 | E9: 11.670962 | F9: 63.720884 | G9: 32.091658 | H9: 2.5680155 | I9: 9.1931436
A10: 1968 | B10: 100 | C10: 21.239823 | D10: 77.692733 | E10: 12.189988 | F10: 65.502745 | G10: 33.346423 | H10: 0.94033442 | I10: 9.260333
A11: 1969 | B11: 100 | C11: 20.297016 | D11: 78.618831 | E11: 12.628561 | F11: 65.99027 | G11: 32.813692 | H11: 1.0965133 | I11: 7.7679799
A12: 1970 | B12: 100 | C12: 19.602459 | D12: 79.307166 | E12: 12.220979 | F12: 67.086187 | G12: 30.627598 | H12: 2.3855637 | I12: 7.2821311
A13: 1971 | B13: 100 | C13: 22.201881 | D13: 78.010736 | E13: 11.61973 | F13: 66.391007 | G13: 36.033865 | H13: 0.58520483 | I13: 7.5720744
A14: 1972 | B14: 100 | C14: 19.931089 | D14: 73.156454 | E14: 11.229686 | F14: 61.926768 | G14: 32.776883 | H14: 0.89311359 | I14: 13.104638
A15: 1973 | B15: 100 | C15: 20.686045 | D15: 68.192278 | E15: 11.185503 | F15: 57.006775 | G15: 28.973488 | H15: -0.70295441 | I15: 24.223233
A16: 1974 | B16: 100 | C16: 27.330922 | D16: 76.204097 | E16: 16.843787 | F16: 59.36031 | G16: 27.383979 | H16: -2.9888707 | I16: 26.731717
A17: 1975 | B17: 100 | C17: 25.985696 | D17: 76.949922 | E17: 15.922943 | F17: 61.02698 | G17: 30.269608 | H17: -0.68099258 | I17: 19.447158
A18: 1976 | B18: 100 | C18: 24.677049 | D18: 77.304183 | E18: 16.319709 | F18: 60.984474 | G18: 29.494072 | H18: -0.70541724 | I18: 18.584212
... A55: 2013 | B55: 100 | C55: 30.633233 | D55: 76.321238 | E55: 14.226964 | F55: 62.094274 | G55: 26.965415 | H55: 0.38681122 | I55: 26.959769
A56: 2014 sd | B56: 100 | C56: 30.727805 | D56: 76.146589 | E56: 14.395627 | F56: 61.750962 | G56: 26.913468 | H56: 0.65517089 | I56: 27.012578
A57: 2015 p | B57: 100 | C57: 28.04666 | D57: 76.023579 | E57: 14.458778 | F57: 61.564801 | G57: 25.297729 | H57: -0.14453793 | I57: 26.869891
A58: 2016 prel | B58: 100 | C58: 26.633327 | D58: 75.505875 | E58: 14.182884 | F58: 61.322991 | G58: 23.610349 | H58: 0.33285243 | I58: 27.184251
A60: (*) Incluye Instituciones sin fines de lucro que sirven a los hogares
A61: sd: semidefinitivo
A62: p: provisional
A63: prel: preliminar por sumatoria de trimestres
A68: regresar al índice

Sheet 4.6
A1: 4.6 OFERTA Y UTILIZACIÓN FINAL DE BIENES Y SERVICIOS
A2: Contribución al crecimiento del PIB
A3: A precios de 2007
A5: AÑOS | B5: Producto interno bruto (PIB) | C5: Importaciones de bienes y servicios | D5: Gobierno general | E5: Hogares residentes(*) | F5: Formación bruta de capital fijo | G5: Variación de existencias | H5: Exportaciones de bienes y servicios
A7: 1966 | B7: -0.33952564 | C7: 0.52192506 | D7: 0.13729155 | E7: 0.44859691 | F7: 0.30295851 | G7: -1.0320133 | H7: 0.32556576
A8: 1967 | B8: 4.6210739 | C8: 3.4315699 | D8: 0.69308619 | E8: 2.145648 | F8: 5.0518903 | G8: -0.49111641 | H8: 0.6531358
A9: 1968 | B9: 1.9094384 | C9: 2.4007214 | D9: 0.75178686 | E9: 3.0325953 | F9: 1.8914938 | G9: -1.609726 | H9: 0.24400973
A10: 1969 | B10: 4.669238 | C10: 0.0049084568 | D10: 1.0282305 | E10: 3.5687674 | F10: 0.99941838 | G10: 0.20737774 | H10: -1.1296476
A11: 1970 | B11: 6.8719293 | C11: 0.65251073 | D11: 0.4322353 | E11: 5.7060324 | F11: -0.081386242 | G11: 1.4529846 | H11: 0.014574038
A12: 1971 | B12: 6.2926062 | C12: 3.9964981 | D12: 0.12993406 | E12: 3.4825445 | F12: 7.6737357 | G12: -1.7635342 | H12: 0.76642421
A13: 1972 | B13: 5.0176407 | C13: -1.2707215 | D13: 0.17342216 | E13: -1.356976 | F13: -1.6123557 | G13: 0.35272199 | H13: 6.1901068
A14: 1973 | B14: 13.950682 | C14: 3.6408002 | D14: 1.5162706 | E14: 3.0328409 | F14: 0.23860397 | G14: -1.6941349 | H14: 14.497902
A15: 1974 | B15: 11.20851 | C15: 9.7082665 | D15: 7.5462217 | E15: 9.0069408 | F15: 1.4798271 | G15: -2.6209241 | H15: 5.5047107
A16: 1975 | B16: 10.972154 | C16: 1.5059641 | D16: 0.82624519 | E16: 8.3626443 | F16: 6.206857 | G16: 2.2331585 | H16: -5.150787
A17: 1976 | B17: 7.3971876 | C17: 0.51676108 | D17: 1.6039654 | E17: 4.4686306 | F17: 1.4061955 | G17: -0.07660569 | H17: 0.5117628
A18: 1977 | B18: 1.6048421 | C18: 4.2703451 | D18: 0.70656865 | E18: 2.2669654 | F18: 2.8842563 | G18: -0.25703037 | H18: 0.27442729
... A47: 2006 | B47: 4.4035264 | C47: 2.7200492 | D47: 0.40335651 | E47: 2.7785211 | F47: 1.0140826 | G47: 0.66180821 | H47: 2.2658072
A48: 2007 | B48: =+'[1]4.5'!B49*'[1]4.3'!B48/100 -> 2.190064 | C48: 2.0644435 | D48: 0.60098029 | E48: 2.7041078 | F48: 0.76155851 | G48: 0.18224522 | H48: 0.0056155897
A49: 2008 | B49: 6.3571306 | C49: 4.4263936 | D49: 1.209892 | E49: 3.5162834 | F49: 3.3176666 | G49: 1.786855 | H49: 0.95282725
A50: 2009 | B50: 0.56649159 | C50: -3.2718648 | D50: 1.3251624 | E50: -0.63863114 | F50: -0.81637358 | G50: -1.0950203 | H50: -1.4805105
A51: 2010 | B51: 3.5252987 | C51: 4.3798741 | D51: 0.55583506 | E51: 4.8980024 | F51: 2.2120036 | G51: 0.30872801 | H51: -0.069396213
A52: 2011 | B52: 7.8681409 | C52: 1.1949405 | D52: 1.1107742 | E52: 3.3887363 | F52: 3.3119831 | G52: -0.34722262 | H52: 1.5988104
A53: 2012 | B53: 5.6419621 | C53: 0.26287867 | D53: 1.4299698 | E53: 1.8502254 | F53: 2.5857617 | G53: -1.4717194 | H53: 1.5106033
A54: 2013 | B54: 4.9465113 | C54: 2.0936141 | D54: 1.3947127 | E54: 2.4554665 | F54: 2.669144 | G54: -0.18498524 | H54: 0.70578749
A55: 2014 sd | B55: 3.9927085 | C55: 1.3214436 | D55: 0.74343862 | E55: 2.1222238 | F55: 1.0226286 | G55: 0.29451873 | H55: 1.1313424
A56: 2015 p | B56: 0.15774372 | C56: -2.6369029 | D56: 0.085958684 | E56: -0.089046535 | F56: -1.5758328 | G56: -0.79993681 | H56: -0.10030174
A57: 2016 prel | B57: -1.4674989 | C57: -1.804177 | D57: -0.48402751 | E57: -1.1417243 | F57: -2.0338616 | G57: 0.47250576 | H57: -0.08456822
A59: (*) Incluye Instituciones sin fines de lucro que sirven a los hogares
A60: sd: semidefinitivo
A61: p: provisional
A62: prel: preliminar por sumatoria de trimestres
A67: regresar al índice

Sheet 4.7
A1: 4.7 ÍNDICE PONDERADO DE PRECIOS AL CONSUMIDOR POR CIUDADES Y POR CATEGORÍAS DE BIENES Y SERVICIOS (1940-2014) (1)
A2: (Familias de ingresos bajos, medios y altos de Quito, Guayaquil y Cuenca) (2)
A3: Base: enero - diciembre de 2004 = 100
A5: Año | C5: Indice Nacional | D5: Por ciudades | G5: Por grupo de bienes y servicios
D6: Quito | E6: Guayaquil | F6: Cuenca | G6: Alimentos | H6: Vivienda | I6: Indumentaria | J6: Diversos
A8: 1940 | C8: 0.0034368997 | D8: 0.0038048745
A9: 1941 | C9: 0.0035546017 | D9: 0.0039351784
A10: 1942 | C10: 0.0045668393 | D10: 0.0050557921
A11: 1943 | C11: 0.0055790769 | D11: 0.0061764058
A12: 1944 | C12: 0.0068502589 | D12: 0.0075836881
A13: 1945 | C13: 0.0088982745 | D13: 0.0098509763
A14: 1946 | C14: 0.010216537 | D14: 0.01131038
A15: 1947 | C15: 0.011676043 | D15: 0.012926149
A16: 1948 | C16: 0.013064927 | D16: 0.014463735
A17: 1949 | C17: 0.012829523 | D17: 0.014203127
A18: 1950 | C18: 0.012758901 | D18: 0.013994641 | G18: 0.01005001 | H18: 0.021469681 | I18: 0.027489974 | J18: 0.012542512
A19: 1951 | C19: 0.014265488 | D19: 0.015792835 | G19: 0.0099265889 | H19: 0.031203224 | I19: 0.029872121 | J19: 0.015372502
A20: 1952 | C20: 0.014736296 | D20: 0.016314051 | G20: 0.010296852 | H20: 0.031715515 | I20: 0.030300908 | J20: 0.015621541
A21: 1953 | C21: 0.014806917 | D21: 0.016392233 | G21: 0.010226326 | H21: 0.032600383 | I21: 0.030634408 | J21: 0.0158253
A22: 1954 | C22: 0.015348346 | D22: 0.016991631 | G22: 0.010878695 | H22: 0.032227807 | I22: 0.031253766 | J22: 0.0158253
A23: 1955 | C23: 0.016054559 | D23: 0.017226178 | E23: 0.018106428 | G23: 0.01214817 | H23: 0.029852636 | I23: 0.034779344 | J23: 0.016391298
A24: 1956 | C24: 0.015583751 | D24: 0.016418294 | E24: 0.017820674 | G24: 0.011566327 | H24: 0.0304115 | I24: 0.032492483 | J24: 0.015598901
A25: 1957 | C25: 0.015748533 | D25: 0.016522537 | E25: 0.018028495 | G25: 0.011760275 | H25: 0.030737504 | I25: 0.032206625 | J25: 0.015168742
A26: 1958 | C26: 0.015913316 | D26: 0.016809206 | E26: 0.018158384 | G26: 0.01181317 | H26: 0.030970364 | I26: 0.032206625 | J26: 0.016096979
A27: 1959 | C27: 0.015866235 | D27: 0.016835266 | E27: 0.018054473 | G27: 0.011513433 | H27: 0.032041519 | I27: 0.033111841 | J27: 0.016210178
A28: 1960 | C28: 0.015960397 | D28: 0.017069813 | E28: 0.018028495 | G28: 0.011390011 | H28: 0.033298963 | I28: 0.033064198 | J28: 0.016459217
A29: 1961 | C29: 0.016760771 | D29: 0.017799515 | E29: 0.019041624 | G29: 0.012130539 | H29: 0.034556406 | I29: 0.035779845 | J29: 0.016866736
A30: 1962 | C30: 0.017043256 | D30: 0.01829467 | E30: 0.019223468 | G30: 0.01214817 | H30: 0.036186425 | I30: 0.037542634 | J30: 0.017342174
A31: 1963 | C31: 0.017561145 | D31: 0.019389223 | E31: 0.019405311 | G31: 0.01258896 | H31: 0.036885005 | I31: 0.038114349 | J31: 0.018949608
A32: 1964 | C32: 0.017796549 | D32: 0.020040743 | E32: 0.02008073 | G32: 0.013012118 | H32: 0.038328736 | I32: 0.036494489 | J32: 0.017862892
A33: 1965 | C33: 0.018926489 | D33: 0.020692262 | E33: 0.021093859 | G33: 0.013629224 | H33: 0.039958755 | I33: 0.038733707 | J33: 0.01854209
A34: 1966 | C34: 0.019632701 | D34: 0.021526208 | E34: 0.021795256 | G34: 0.014299225 | H34: 0.041076482 | I34: 0.040353567 | J34: 0.019357126
... A36: 1968 | C36: 0.021186368 | D36: 0.023298341 | E36: 0.023483804 | G36: 0.015797911 | H36: 0.042706502 | I36: 0.040687068 | J36: 0.02094192
A37: 1969 | C37: 0.022292767 | D37: 0.024809866 | E37: 0.024600843 | F37: 0.01565664 | G37: 0.017032122 | H37: 0.043451653 | I37: 0.043259786 | J37: 0.021304159
A38: 1970 | C38: 0.023540409 | D38: 0.026060784 | E38: 0.025977659 | F38: 0.016944416 | G38: 0.017631597 | H38: 0.046571976 | I38: 0.047642937 | J38: 0.022639914
A39: 1971 | C39: 0.025776747 | D39: 0.02824989 | E39: 0.028523469 | F39: 0.019181079 | G39: 0.019006861 | H39: 0.051694893 | I39: 0.053836518 | J39: 0.024858625
A40: 1972 | C40: 0.027754142 | D40: 0.030491117 | E40: 0.030653637 | F40: 0.02060441 | G40: 0.020946337 | H40: 0.054815215 | I40: 0.057457381 | J40: 0.025673662
A41: 1973 | C41: 0.031073339 | D41: 0.034426296 | E41: 0.034212577 | F41: 0.022688573 | G41: 0.024560814 | H41: 0.057935538 | I41: 0.063555677 | J41: 0.027484856
A42: 1974 | C42: 0.038135462 | D42: 0.042479078 | E42: 0.041798053 | F42: 0.027958286 | G42: 0.032212927 | H42: 0.064874762 | I42: 0.076943343 | J42: 0.030835563
A43: 1975 | C43: 0.043997024 | D43: 0.048994274 | E43: 0.047435205 | F43: 0.032313001 | G43: 0.037925564 | H43: 0.075027453 | I43: 0.089187577 | J43: 0.032895795
...

Sheet 4.7.a
A1: 4.7.a ÍNDICE PONDERADO DE PRECIOS AL CONSUMIDOR POR CIUDADES Y POR CATEGORÍAS DE BIENES Y SERVICIOS (2015-2016) (1)
A2: (Familias de ingresos bajos, medios y altos de Quito, Guayaquil y Cuenca) (2)
A3: Base: enero - diciembre de 2014 = 100
A5: Año | C5: Indice Nacional | D5: Por ciudades | G5: Por grupo de bienes y servicios
D6: Quito | E6: Guayaquil | F6: Cuenca | G6: Alimentos | H6: Vivienda | I6: Indumentaria | J6: Diversos
A8: 2015 | C8: 103.22038 | D8: 102.83804 | E8: 103.38543 | F8: 103.23524 | G8: 104.31401 | H8: 107.20527 | I8: 98.61046 | J8: 102.55659
A9: 2016 | C9: 105.0043 | D9: 104.85543 | E9: 105.15814 | F9: 105.47547 | G9: 107.27835 | H9: 110.57192 | I9: 98.149169 | J9: 104.58089
A14: regresar al índice

Sheet 4.8
A1: 4.8 ÍNDICE PONDERADO DE PRECIOS AL CONSUMIDOR POR DIVISIONES DE BIENES Y SERVICIOS (1997-2004) (1)
A2: De las familias de ingresos bajos y medios
A3: Base: septiembre 1994 - agosto 1995 = 100
A5: Año | B5: ÍNDICE GENERAL | C5: Alimentos, bebidas y tabaco | D5: Vestido y calzado | E5: Alquiler, agua, electricidad, gas y otros combustibles | F5: Muebles, equipamiento y mantenimiento de la vivienda | G5: Salud | H5: Transporte | I5: Esparcimiento y cultura | J5: Educación | K5: Hoteles, cafeterías y restaurantes | L5: Bienes y servicios misceláneos
A7: 1997 | B7: 177.11 | C7: 181.2 | D7: 167.11 | E7: 197.1 | F7: 160.48 | G7: 169.97 | H7: 180.38 | I7: 147.8 | J7: 186.09 | K7: 178.88 | L7: 159.59
A8: 1998 | B8: 241.04 | C8: 253.01 | D8: 204.95583 | E8: 303.905 | F8: 206.17917 | G8: 225.29833 | H8: 255.26833 | I8: 192.20083 | J8: 237.7275 | K8: 242.53417 | L8: 196.495
A9: 1999 | B9: 366.96 | C9: 351.78 | D9: 323.4025 | E9: 481.05 | F9: 348.77167 | G9: 363.70083 | H9: 438.75417 | I9: 361.74167 | J9: 325.04917 | K9: 343.51083 | L9: 338.725
A10: 2000 | B10: 719.61 | C10: 776.77 | D10: 709.17083 | E10: 632.27417 | F10: 748.4225 | G10: 774.29417 | H10: 816.65667 | I10: 775.985 | J10: 520.34833 | K10: 626.4525 | L10: 752.55583
A11: 2001 | B11: 990.73 | C11: 1023.04 | D11: 926.26667 | E11: 956.58417 | F11: 971.67417 | G11: 1061.6858 | H11: 1211.73 | I11: 952.75917 | J11: 886.92667 | K11: 907.7375 | L11: 987.1075
A12: 2002 | B12: 1114.42 | C12: 1106.87 | D12: 939.48333 | E12: 1403.9417 | F12: 1027.8892 | G12: 1195.035 | H12: 1233.2667 | I12: 964.39583 | J12: 1237.2675 | K12: 1029.4408 | L12: 1009.2567
A13: 2003 | B13: 1202.78 | C13: 1133.78 | D13: 883.90583 | E13: 1806.3392 | F13: 1013.0475 | G13: 1257.5717 | H13: 1426.35 | I13: 942.22917 | J13: 1534.3642 | K13: 1113.8567 | L13: 951.625
A14: 2004 | B14: 1235.7616 | C14: 1147.3967 | D14: 821.95322 | E14: 2021.6127 | F14: 998.20914 | G14: 1281.0703 | H14: 1436.6306 | I14: 881.18601 | J14: 1787.736 | K14: 1126.9917 | L14: 869.16498
A19: regresar al índice

Sheet 4.8.a
A1: 4.8.a ÍNDICE PONDERADO DE PRECIOS AL CONSUMIDOR POR DIVISIONES DE BIENES Y SERVICIOS (2005 - 2014)
A2: De las familias de ingresos bajos, medios y altos
A3: Base: enero - diciembre 2004 = 100
A5: Año | B5: ÍNDICE GENERAL | C5: Alimentos y Bebidas No Alcohólicas (1) | D5: Bebidas Alcohólicas, Tabaco y estupefacientes (1) | E5: Prendas de Vestir y calzado | F5: Alojamiento, agua, gas, electricidad y otros | G5: Muebles, artículos para el hogar y conservación ordinaria | H5: Salud | I5: Transporte | J5: Comunicaciones (2) | K5: Recreación y Cultura | L5: Educación | M5: Restaurantes y Hoteles | N5: Bienes y Servicios Diversos (2)
A7: 2005 | B7: 102.07999 | C7: 102.89788 | D7: 106.14221 | E7: 99.610989 | F7: 102.87035 | G7: 99.534134 | H7: 101.32959 | I7: 102.2389 | J7: 98.452844 | K7: 102.52963 | L7: 109.35368 | M7: 100.97228 | N7: 98.133942
A8: 2006 | B8: 105.44713 | C8: 108.74206 | D8: 110.02359 | E8: 100.24561 | F8: 107.81476 | G8: 101.70223 | H8: 102.89166 | I8: 105.01333 | J8: 97.729633 | K8: 101.71577 | L8: 118.98487 | M8: 102.45316 | N8: 98.670906
A9: 2007 | B9: 107.84753 | C9: 112.28075 | D9: 115.57655 | E9: 101.07987 | F9: 110.31948 | G9: 105.00023 | H9: 105.2924 | I9: 107.85789 | J9: 97.181676 | K9: 99.778047 | L9: 125.27693 | M9: 104.05184 | N9: 98.730276
A10: 2008 | B10: 116.90683 | C10: 131.18691 | D10: 137.97387 | E10: 107.50349 | F10: 115.30278 | G10: 118.67497 | H10: 108.61897 | I10: 110.85217 | J10: 95.614296 | K10: 101.25149 | L10: 131.2337 | M10: 114.02753 | N10: 108.01155
A11: 2009 | B11: 122.93918 | C11: 138.90809 | D11: 155.80713 | E11: 114.03509 | F11: 117.79963 | G11: 128.64116 | H11: 112.19002 | I11: 113.22832 | J11: 95.940309 | K11: 103.30237 | L11: 136.34023 | M11: 122.66712 | N11: 124.74612
A12: 2010 | B12: 127.3089 | C12: 145.61615 | D12: 165.4898 | E12: 119.02618 | F12: 120.77793 | G12: 131.70072 | H12: 116.36557 | I12: 114.90436 | J12: 96.111224 | K12: 105.40435 | L12: 141.1002 | M12: 129.60174 | N12: 129.5941
A13: 2011 | B13: 133.00538 | C13: 155.40971 | D13: 172.40961 | E13: 126.70894 | F13: 123.38695 | G13: 137.72211 | H13: 120.04391 | I13: 117.57101 | J13: 98.082725 | K13: 105.60302 | L13: 147.83742 | M13: 135.98398 | N13: 134.92425
A14: 2012 | B14: 139.79095 | C14: 164.44104 | D14: 211.29222 | E14: 132.30094 | F14: 126.54439 | G14: 143.11787 | H14: 125.42093 | I14: 123.55702 | J14: 97.525656 | K14: 109.52802 | L14: 157.14707 | M14: 146.60413 | N14: 140.99481
A15: 2013 | B15: 143.59574 | C15: 167.37241 | D15: 235.42971 | E15: 135.11549 | F15: 129.3192 | G15: 146.73959 | H15: 130.93791 | I15: 124.73274 | J15: 97.553326 | K15: 110.4467 | L15: 166.794 | M15: 155.98096 | N15: 145.86827
A16: 2014 | B16: 148.74971 | C16: 174.93937 | D16: 250.1307 | E16: 138.00247 | F16: 134.11305 | G16: 150.42215 | H16: 135.55146 | I16: 125.34715 | J16: 97.180811 | K16: 112.76733 | L16: 176.54408 | M16: 164.49258 | N16: 154.00957
A21: regresar al índice

Sheet 4.8.b
A1: 4.8.b ÍNDICE PONDERADO DE PRECIOS AL CONSUMIDOR POR DIVISIONES DE BIENES Y SERVICIOS (2015 - 2016)
A2: De las familias de ingresos bajos, medios y altos
A3: Base: enero - diciembre 2014 = 100
A5: Año | B5: ÍNDICE GENERAL | C5: Alimentos y Bebidas No Alcohólicas (1) | D5: Bebidas Alcohólicas, Tabaco y estupefacientes (1) | E5: Prendas de Vestir y calzado | F5: Alojamiento, agua, gas, electricidad y otros | G5: Muebles, artículos para el hogar y conservación ordinaria | H5: Salud | I5: Transporte | J5: Comunicaciones (2) | K5: Recreación y Cultura | L5: Educación | M5: Restaurantes y Hoteles | N5: Bienes y Servicios Diversos (2)
A7: 2015 | B7: 103.22038 | C7: 104.13818 | D7: 108.75299 | E7: 97.329532 | F7: 107.28025 | G7: 104.13149 | H7: 102.81952 | I7: 104.63374 | J7: 95.082696 | K7: 99.29541 | L7: 102.16304 | M7: 105.6297 | N7: 104.18779
A8: 2016 | B8: 105.0043 | C8: 106.77876 | D8: 124.87976 | E8: 94.235301 | F8: 110.99719 | G8: 104.60875 | H8: 105.7043 | I8: 105.51381 | J8: 94.437888 | K8: 99.207773 | L8: 104.53354 | M8: 108.72719 | N8: 107.38748
A13: regresar al índice

Sheet 4.9
A1: 4.9 VARIACIÓN ANUAL DEL ÍNDICE PONDERADO DE PRECIOS AL CONSUMIDOR POR CIUDADES Y POR CATEGORÍAS DE BIENES
A2: Y SERVICIOS (1940-2014) (1)
A3: (Familias de ingresos bajos, medios y altos de Quito, Guayaquil y Cuenca) (2)
A4: Base: enero - diciembre de 2004 = 100
A6: Año | C6: Nacional | D6: Por ciudades | G6: Por grupo de bienes y servicios
D7: Quito | E7: Guayaquil | F7: Cuenca | G7: Alimentos | H7: Vivienda | I7: Indumentaria | J7: Diversos
A9: 1940 | C9: 3.55 | D9: 3.55
A10: 1941 | C10: 3.4246575 | D10: 3.4246575
A11: 1942 | C11: 28.476821 | D11: 28.476821
A12: 1943 | C12: 22.164948 | D12: 22.164948
A13: 1944 | C13: 22.78481 | D13: 22.78481
A14: 1945 | C14: 29.896907 | D14: 29.896907
A15: 1946 | C15: 14.814815 | D15: 14.814815
A16: 1947 | C16: 14.285714 | D16: 14.285714
A17: 1948 | C17: 11.895161 | D17: 11.895161
A18: 1949 | C18: -1.8018018 | D18: -1.8018018
A19: 1950 | C19: -0.55045872 | D19: -1.4678899
A20: 1951 | C20: 11.808118 | D20: 12.849162
A21: 1952 | C21: 3.30033 | D21: 3.30033
A22: 1953 | C22: 0.47923323 | D22: 0.47923323 | G22: -0.68493151 | H22: 2.7900147 | I22: 1.1006289 | J22: 1.3043478
A23: 1954 | C23: 3.6565978 | D23: 3.6565978 | G23: 6.3793103 | H23: -1.1428571 | I23: 2.0217729 | J23: 0
A24: 1955 | C24: 4.601227 | D24: 1.3803681 | G24: 11.669368 | H24: -7.3699422 | I24: 11.280488 | J24: 3.5765379
A25: 1956 | C25: -2.9325513 | D25: -4.6898638 | G25: -4.7895501 | H25: 1.8720749 | I25: -6.5753425 | J25: -4.8342541
A26: 1957 | C26: 1.0574018 | D26: 0.63492063 | G26: 1.6768293 | H26: 1.0719755 | I26: -0.8797654 | J26: -2.7576197
A27: 1958 | C27: 1.0463378 | D27: 1.7350158 | E27: 0.7204611 | G27: 0.44977511 | H27: 0.75757576 | I27: 0 | J27: 6.119403
A28: 1959 | C28: -0.29585799 | D28: 0.15503876 | E28: -0.57224607 | G28: -2.5373134 | H28: 3.4586466 | I28: 2.8106509 | J28: 0.70323488
A29: 1960 | C29: 0.59347181 | D29: 1.3931889 | E29: -0.14388489 | G29: -1.0719755 | H29: 3.9244186 | I29: -0.14388489 | J29: 1.5363128
A30: 1961 | C30: 5.0147493 | D30: 4.2748092 | E30: 5.6195965 | G30: 6.501548 | H30: 3.7762238 | I30: 8.2132565 | J30: 2.4759285
A31: 1962 | C31: 1.6853933 | D31: 2.7818448 | E31: 0.95497954 | G31: 0.14534884 | H31: 4.7169811 | I31: 4.9267643 | J31: 2.8187919
A32: 1963 | C32: 3.038674 | D32: 5.982906 | E32: 0.94594595 | G32: 3.628447 | H32: 1.9305019 | I32: 1.5228426 | J32: 9.2689295
A33: 1964 | C33: 1.3404826 | D33: 3.3602151 | E33: 3.480589 | G33: 3.3613445 | H33: 3.9141414 | I33: -4.25 | J33: -5.734767
A34: 1965 | C34: 6.3492063 | D34: 3.2509753 | E34: 5.0452781 | G34: 4.7425474 | H34: 4.2527339 | I34: 6.1357702 | J34: 3.8022814
A35: 1966 | C35: 3.7313433 | D35: 4.0302267 | E35: 3.3251232 | G35: 4.915912 | H35: 2.7972028 | I35: 4.1820418 | J35: 4.3956044
A36: 1967 | C36: 4.7961631 | D36: 3.874092 | E36: 5.601907 | G36: 6.4118372 | H36: 2.0408163 | I36: -0.47225502 | J36: 6.1988304
A37: 1968 | C37: 2.9748284 | D37: 4.1958042 | E37: 2.0316027 | G37: 3.8238702 | H37: 1.8888889 | I37: 1.3048636 | J37: 1.8722467
A38: 1969 | C38: 5.2222222 | D38: 6.4876957 | E38: 4.7566372 | G38: 7.8125 | H38: 1.7448201 | I38: 6.323185 | J38: 1.7297297
... A40: 1971 | C40: 9.5 | D40: 8.4 | E40: 9.8 | G40: 7.8 | H40: 11 | I40: 13 | J40: 9.8
A41: 1972 | C41: 7.6712329 | D41: 7.9335793 | E41: 7.4681239 | F41: 7.4204947 | G41: 10.204082 | H41: 6.036036 | I41: 6.7256637 | J41: 3.2786885
A42: 1973 | C42: 11.959288 | D42: 12.905983 | E42: 11.610169 | F42: 10.115132 | G42: 17.255892 | H42: 5.6924384 | I42: 10.613599 | J42: 7.0546737
A43: 1974 | C43: 22.727273 | D43: 23.39137 | E43: 22.171602 | F43: 23.226288 | G43: 31.155779 | H43: 11.977492 | I43: 21.064468 | J43: 12.191104
...

Sheet 4.9.a
A1: 4.9.a VARIACIÓN ANUAL DEL ÍNDICE PONDERADO DE PRECIOS AL CONSUMIDOR POR CIUDADES Y POR CATEGORÍAS DE BIENES
A2: Y SERVICIOS (2015-2016) (1)
A3: (Familias de ingresos bajos, medios y altos de Quito, Guayaquil y Cuenca) (2)
A4: Base: enero - diciembre de 2014 = 100
A6: Año | C6: Nacional | D6: Por ciudades | G6: Por grupo de bienes y servicios
D7: Quito | E7: Guayaquil | F7: Cuenca | G7: Alimentos | H7: Vivienda | I7: Indumentaria | J7: Diversos
A9: 2015 | C9: 3.9666462 | D9: - | E9: - | F9: - | G9: - | H9: - | I9: - | J9: -
A10: 2016 | C10: 1.7282646 | D10: 1.9617116 | E10: 1.7146613 | F10: 2.1700241 | G10: 2.8417488 | H10: 3.1403817 | I10: -0.46779093 | J10: 1.9738383
A15: regresar al índice

Sheet 4.10
A1: 4.10 VARIACIÓN ANUAL DEL ÍNDICE PONDERADO DE PRECIOS AL CONSUMIDOR POR DIVISIONES DE BIENES Y SERVICIOS (1997-2004) (1)
A2: Familias de ingresos bajos y medios
A3: Base: septiembre, 1994 - agosto, 1995 = 100
A5: Año | B5: GENERAL | C5: Alimentos Bebidas y Tabaco | D5: Vestido y Calzado | E5: Alquiler, Agua, Gas, Electricidad y otros | F5: Muebles, Equipamiento, Mantenimiento de Vivienda | G5: Salud | H5: Transporte | I5: Esparcimiento y Cultura | J5: Educación | K5: Hoteles, Cafeterías y Restaurantes | L5: Bienes y Servicios Misceláneos | M5: Valores de las UVC (1)
A7: 1997 | B7: 30.6 | C7: - | D7: - | E7: - | F7: - | G7: - | H7: - | I7: - | J7: - | K7: - | L7: -
A8: 1998 | B8: 36.096211 | C8: 39.630243 | D8: 22.647258 | E8: 54.188229 | F8: 28.47655 | G8: 32.551823 | H8: 41.516983 | I8: 30.041159 | J8: 27.74867 | K8: 35.584843 | L8: 23.124883
A9: 1999 | B9: 52.240292 | C9: 39.037983 | D9: 57.791313 | E9: 58.289597 | F9: 69.159509 | G9: 61.43077 | H9: 71.879591 | I9: 88.210249 | J9: 36.731832 | K9: 41.633997 | L9: 72.383521
A10: 2000 | B10: 96.100392 | C10: 120.8113 | D10: 119.28428 | E10: 31.436268 | F10: 114.5881 | G10: 112.89315 | H10: 86.130806 | I10: 114.51358 | J10: 60.082962 | K10: 82.367611 | L10: 122.1731
A11: 2001 | B11: 37.675963 | C11: 31.704366 | D11: 30.612629 | E11: 51.292622 | F11: 29.829631 | G11: 37.1166 | H11: 48.376919 | I11: 22.780616 | J11: 70.448642 | K11: 44.901249 | L11: 31.167344
A12: 2002 | B12: 12.484733 | C12: 8.1942055 | D12: 1.4268749 | E12: 46.766141 | F12: 5.7853756 | G12: 12.560134 | H12: 1.7773486 | I12: 1.221365 | J12: 39.500541 | K12: 13.407327 | L12: 2.2438454
A13: 2003 | B13: 7.9287881 | C13: 2.4311798 | D13: -5.9157516 | E13: 28.661981 | F13: -1.4438976 | G13: 5.2330406 | H13: 15.656252 | I13: -2.2985029 | J13: 24.012323 | K13: 8.2001637 | L13: -5.7103082
A14: 2004 | B14: 2.7421162 | C14: 1.2010013 | D14: -7.0089606 | E14: 11.917668 | F14: -1.4647245 | G14: 1.8685689 | H14: 0.72076008 | I14: -6.4785892 | J14: 16.51315 | K14: 1.1792385 | L14: -8.6651803
A19: regresar al índice

Sheet 4.10.a
A1: 4.10.a VARIACIÓN ANUAL DEL ÍNDICE PONDERADO DE PRECIOS AL CONSUMIDOR POR DIVISIONES DE BIENES Y SERVICIOS (2005-2014)
A2: De las familias de ingresos altos, medios y bajos
A3: Base: enero - diciembre 2004 = 100
A5: Año | B5: GENERAL | C5: Alimentos y Bebidas No Alcohólicas (1) | D5: Bebidas Alcohólicas, Tabaco y estupefacientes (1) | E5: Prendas de Vestir y calzado | F5: Alojamiento, agua, gas, electricidad y otros | G5: Muebles y artículos para el hogar y conservación ordinaria | H5: Salud | I5: Transporte | J5: Comunicaciones (2) | K5: Recreación y Cultura | L5: Educación | M5: Restaurantes y Hoteles | N5: Bines y Servicios Diversos (2)
A7: 2005 | B7: 2.1230811 | C7: 2.7320285 | D7: 6.59156 | E7: -0.25049528 | F7: 3.3723294 | G7: -0.1087591 | H7: 0.96589085 | I7: 2.2797225 | J7: -1.8119741 | K7: 2.6567139 | L7: 9.8560489 | M7: 0.80449923 | N7: -2.1183105
A8: 2006 | B8: 3.2985304 | C8: 5.6795898 | D8: 3.6567762 | E8: 0.63709878 | F8: 4.8064471 | G8: 2.1782394 | H8: 1.5415714 | I8: 2.7136734 | J8: -0.73457578 | K8: -0.79378763 | L8: 8.8073694 | M8: 1.4666139 | N8: 0.54717395
A9: 2007 | B9: 2.2764006 | C9: 3.2542088 | D9: 5.0470677 | E9: 0.83221853 | F9: 2.3231697 | G9: 3.2428004 | H9: 2.3332688 | I9: 2.7087614 | J9: -0.56068657 | K9: -1.9050321 | L9: 5.2881225 | M9: 1.5604094 | N9: 0.060169415
A10: 2008 | B10: 8.4000959 | C10: 16.838291 | D10: 19.378768 | E10: 6.354994 | F10: 4.5171537 | G10: 13.023537 | H10: 3.1593689 | I10: 2.7761371 | J10: -1.6128349 | K10: 1.4767206 | L10: 4.7548779 | M10: 9.5872308 | N10: 9.400636
A11: 2009 | B11: 5.1599683 | C11: 5.8856364 | D11: 12.9251 | E11: 6.0757103 | F11: 2.1654702 | G11: 8.397889 | H11: 3.2876815 | I11: 2.1435323 | J11: 0.34096668 | K11: 2.0255339 | L11: 3.891173 | M11: 7.5767517 | N11: 15.493312
A12: 2010 | B12: 3.5543773 | C12: 4.8291339 | D12: 6.2145287 | E12: 4.3768012 | F12: 2.5282762 | G12: 2.3783693 | H12: 3.721854 | I12: 1.4802244 | J12: 0.17814692 | K12: 2.0347795 | L12: 3.4912479 | M12: 5.6532034 | N12: 3.8862829
A13: 2011 | B13: 4.4745327 | C13: 6.7256017 | D13: 4.1814064 | E13: 6.4546794 | F13: 2.1601804 | G13: 4.5720244 | H13: 3.1610212 | I13: 2.3207566 | J13: 2.0512706 | K13: 0.18848799 | L13: 4.7747705 | M13: 4.9245013 | N13: 4.1129537
A14: 2012 | B14: 5.1017218 | C14: 5.8113003 | D14: 22.552464 | E14: 4.4132623 | F14: 2.5589722 | G14: 3.9178577 | H14: 4.4792145 | I14: 5.0913974 | J14: -0.56795833 | K14: 3.7167429 | L14: 6.2972258 | M14: 7.8098542 | N14: 4.499237
A15: 2013 | B15: 2.7217758 | C15: 1.7826252 | D15: 11.423747 | E15: 2.1273838 | F15: 2.1927573 | G15: 2.5305891 | H15: 4.3987719 | I15: 0.95156755 | J15: 0.028372047 | K15: 0.8387637 | L15: 6.1387928 | M15: 6.3960192 | N15: 3.4564842
A16: 2014 | B16: 3.5892202 | C16: 4.521033 | D16: 6.2443227 | E16: 2.1366807 | F16: 3.7069878 | G16: 2.5095882 | H16: 3.5234629 | I16: 0.49258189 | J16: -0.38185777 | K16: 2.1011366 | L16: 5.8455774 | M16: 5.4568354 | N16: 5.5812676
A21: regresar al índice

Sheet 4.10.b
A1: 4.10.b VARIACIÓN ANUAL DEL ÍNDICE PONDERADO DE PRECIOS AL CONSUMIDOR POR DIVISIONES DE BIENES Y SERVICIOS (2015-2016)
A2: De las familias de ingresos altos, medios y bajos
A3: Base: enero - diciembre 2014 = 100
A5: Año | B5: GENERAL | C5: Alimentos y Bebidas No Alcohólicas (1) | D5: Bebidas Alcohólicas, Tabaco y estupefacientes (1) | E5: Prendas de Vestir y calzado | F5: Alojamiento, agua, gas, electricidad y otros | G5: Muebles y artículos para el hogar y conservación ordinaria | H5: Salud | I5: Transporte | J5: Comunicaciones (2) | K5: Recreación y Cultura | L5: Educación | M5: Restaurantes y Hoteles | N5: Bines y Servicios Diversos (2)
A7: 2015 | B7: 3.9666462 | C7: - | D7: - | E7: - | F7: - | G7: - | H7: - | I7: - | J7: - | K7: - | L7: - | M7: - | N7: -
A8: 2016 | B8: =+'4.8.b'!B8/'4.8.b'!B7*100-100 -> 1.7282646 | C8: =+'4.8.b'!C8/'4.8.b'!C7*100-100 -> 2.5356521 | D8: =+'4.8.b'!D8/'4.8.b'!D7*100-100 -> 14.828801 | E8: =+'4.8.b'!E8/'4.8.b'!E7*100-100 -> -3.1791286 | F8: =+'4.8.b'!F8/'4.8.b'!F7*100-100 -> 3.4647038 | G8: =+'4.8.b'!G8/'4.8.b'!G7*100-100 -> 0.45832614 | H8: =+'4.8.b'!H8/'4.8.b'!H7*100-100 -> 2.8056721 | I8: =+'4.8.b'!I8/'4.8.b'!I7*100-100 -> 0.84109416 | ... N8: =+'4.8.b'!N8/'4.8.b'!N7*100-100 -> 3.0710812
A13: regresar al índice

Sheet 4.11
A1: 4.11 SALARIO MÍNIMO VITAL (1936 - 1968) (1)
A3: Año | B3: Fecha de vigencia | C3: Clase de trabajador | D3: Región | E3: Incrementos
F4: -en sucres-
F5: mensual | G5: diario
A7: 1936 | B7: 4-II-1937 | C7: Obrero manual | D7: Sierra | G7: mínimo 1,00
D8: Costa | G8: mínimo 2,00
D9: Quito | G9: mínimo 1,50
C11: Trabajador agrícola | D11: Sierra | G11: mínimo 0,65
D12: Costa | G12: mínimo 1,20
A14: 1942 | B14: 14-II-1942 | C14: Empleados privados | E14: incremento
C15: y obreros | E15: del 25% | F15: hasta 100 | G15: hasta 3,0
E16: incremento
E17: del 20% | F17: 101 a 200 | G17: 3,05 a 6,00
E18: incremento
E19: del 15% | F19: 201 a 300 | G19: 6,05 a 10,00
E20: incremento
E21: del 10% | F21: 301 a 500 | G21: 10,05 a 16,00
C22: Trabajador agrícola | D22: Sierra | F22: no menos de
F23: 1,00 diario
A25: 1953 | B25: 1-VIII-1953 | C25: Empleados privados
C26: y obreros | D26: Costa | E26: incremento
E27: del 40% | F27: hasta 200 | G27: hasta 7,00
E28: incremento
E29: del 30% | F29: 201 a 300 | G29: 7,05 a 10,00
E30: incremento
E31: del 25% | F31: 301 a 400 | G31: 10,05 a 14,00
E32: incremento
E33: del 15% | F33: 401 a 500 | G33: 14,05 a 17,00
D34: Sierra | E34: incremento
E35: del 30% | F35: hasta 200 | G35: hasta 7,00
E36: incremento
E37: del 20% | F37: 201 a 300 | G37: 7,05 a 10,00
E38: incremento
E39: del 15% | F39: 301 a 400 | G39: 10,05 a 14,00
E40: incremento
E41: del 10% | F41: 401 a 500 | G41: 14,05 a 17,00
A43: 1960 | B43: 4-IX-1960 | C43: Trabajador agrícola: | D43: Sierra
C44: Jornaleros | G44: mínimo 6,00
C45: Huasipungueros | G45: mínimo 3,00
A47: 1965 | B47: 24-VII-1965 | C47: Trabajador agrícola: | D47: Sierra
...

Sheet 4.12
A1: 4.12 SALARIO MÍNIMO VITAL GENERAL (S.M.V) Y SALARIO BÁSICO
A2: UNIFICADO (S.B.U.) (1968-2016) (1)
A4: Año | B4: Sucres | C4: Dólares
A7: 1968 oct. | B7: 600 | C7: 27
A8: 1969 | B8: 600 | C8: 27
A9: 1970 | B9: 600 | C9: 26
A10: 1971 | B10: 750 | C10: 29
A11: 1972 | B11: 750 | C11: 29
A12: 1973 | B12: 750 | C12: 30
A13: 1974 | B13: 1000 | C13: 40
A14: 1975 ene | B14: 1000 | C14: 40
A15: 1975 may | B15: 1250 | C15: 50
A16: 1976 | B16: 1500 | C16: 56
A17: 1977 | B17: 1500 | C17: 55
A18: 1978 | B18: 1500 | C18: 56
A19: 1979 | B19: 2000 | C19: 72
A20: 1980 | B20: 4000 | C20: 144
A21: 1981 | B21: 4000 | C21: 128
A22: 1982 ene | B22: 4000 | C22: 115
A23: 1982 nov | B23: 4600 | C23: 78
A24: 1983 ene | B24: 4600 | C24: 69
A25: 1983 jul | B25: 5600 | C25: 57
A26: 1984 | B26: 6600 | C26: 67
A27: 1985 ene | B27: 6600 | C27: 54
A28: 1985 mar | B28: 8500 | C28: 70
A29: 1986 ene | B29: 10000 | C29: 76
A30: 1986 ago | B30: 12000 | C30: 71
A31: 1987 ene | B31: 12000 | C31: 82
A32: 1987 jul | B32: 14500 | C32: 74
A33: 1988 ene | B33: 14500 | C33: 54
A34: 1988 jun | B34: 19000 | C34: 38
A35: 1988 sep | B35: 22000 | C35: 42
A36: 1989 ene | B36: 22000 | C36: 41
A37: 1989 may | B37: 27000 | C37: 50
A38: 1990 | B38: 32000 | C38: 39
A39: 1991 | B39: 40000 | C39: 36
A40: 1992 ene | B40: 40000 | C40: 30
A41: 1992 jun | B41: 60000 | C41: 40
A42: 1993 ene | B42: 60000 | C42: 32
A43: 1993 jul | B43: 66000 | C43: 34
...

Sheet 4.13
A1: 4.13 POBLACIÓN
A3: Año | B3: Población total (1)
A6: 1927 | B6: 2257357.5
A7: 1928 | B7: 2297561
A8: 1929 | B8: 2338480.6
A9: 1930 | B9: 2380128.9
A10: 1931 | B10: 2422519
A11: 1932 | B11: 2465664.1
A12: 1933 | B12: 2509577.6
A13: 1934 | B13: 2554273.1
A14: 1935 | B14: 2599764.7
A15: 1936 | B15: 2646066.6
A16: 1937 | B16: 2693193
A17: 1938 | B17: 2741158.8
... A79: 2000 | B79: 12298745
A80: 2001 (2) | B80: 12156608
A81: 2002 | B81: 12660727
A82: 2003 | B82: 12842576
A83: 2004 | B83: 13026890
A84: 2005 | B84: 13215089
A85: 2006 | B85: 13408270
A86: 2007 | B86: 13605486
A87: 2008 | B87: 13805092
A88: 2009 | B88: 14005449
A89: 2010 | B89: 14204900
A90: 2010 (3) | B90: 14483399
A91: 2010 (4) | B91: 15012228
A92: 2011 | B92: 15266431
A93: 2012 | B93: 15520973
A94: 2013 | B94: 15774749
A95: 2014 | B95: 16027466
A96: 2015 | B96: 16278844
A97: 2016 | B97: 16528730
A102: regresar al índice

Sheet 4.14
A1: 4.14 CANASTA DE BIENES Y SERVICIOS PARA EL CÁLCULO DEL ÍNDICE DE
A2: PRECIOS AL CONSUMIDOR - COMPONENTES Y PONDERADORES -
A3: Base: agosto 1950-julio1951
A5: ALIMENTOS | B5: 52
A7: Carnes y pescados | B7: 8.3
A8: Carne de res de 1ra. | B8: 6.7
A9: Carne de res de 2da. | B9: 0.4
A10: Carne de cordero | B10: 0.1
A11: Carne de cerdo | B11: 1.1
A12: Corvina | B12: X
A14: Cereales y harinas | B14: 13.6
A15: Arroz de castilla | B15: 3.7
A16: Arroz de cebada | B16: 0.3
A17: Avena en paquete | B17: 0.3
A18: Avena suelta | B18: 0.3
A19: Fideos | B19: 1.3
A20: Harina de cebada | B20: 0.6
A21: Harina de habas | B21: 0.2
A22: Harina de plátano | B22: 0.1
A23: Harina de trigo importada | B23: 0.2
A24: Harina de trigo nacional | B24: 0.1
A25: Maíz | B25: 0.6
... A107: Reparación corridas (mujer) | B107: 0.4
A108: Zapatos de niño | B108: X
A109: Zapatos para hombre | B109: 1.2
A110: Reparación corridas (hombre) | B110: 0.6
A112: Telas | B112: 4.7
A113: Lienzo "Vencedor" | B113: 0.2
A114: Peter Pan | B114: 0.1
A115: Gabardina algodón | B115: 0.1
A116: Bramante algodón | B116: 0.3
A117: Franela | B117: 0.7
A118: Seda opaca | B118: 0.5
A119: Terciopelo de lana | B119: 0.5
A120: Casimir nacional | B120: 0.3
A121: Casimir extranjero | B121: 2
... A132: ENSERES DOMESTICOS | B132: 3
A133: Sillas de eucalipto | B133: X
A134: Sillas de cedro | B134: 0.1
A135: Camas de hierro | B135: 0.9
...

Sheet 4.15
A1: 4.15 CANASTA DE BIENES Y SERVICIOS PARA EL CÁLCULO DEL ÍNDICE DE
A2: PRECIOS AL CONSUMIDOR - COMPONENTES Y PONDERADORES -
A3: Base: 1965
A5: ALIMENTOS Y BEBIDAS | B5: 41.8
A7: Cereales y derivados | B7: 10.2
A8: Pan de trigo | B8: 6.0792
A9: Fideo al detal | B9: 0.8364
A10: Arroz de castilla | B10: 2.9274
A11: Avena al detal | B11: 0.357
A13: Carnes y preparaciones de carnes | B13: 6.8
A14: Carne de res con hueso (costilla) | B14: 4.046
A15: Carne de res sin hueso | B15: 2.1556
A16: Carne de gallina | B16: 0.5984
A18: Pescados y mariscos | B18: 0.5
A19: Corvina de mar | B19: 0.222
... A68: Ajo | B68: 0.1344
A70: Café, té y otras bebidas no alcohólicas
A71: consumidas en el hogar | B71: 1.8
A72: Café molido | B72: 0.8766
A73: Café soluble (si café) | B73: 0.4824
A74: Chocolate en pasta | B74: 0.2034
A75: Bebidas gaseosas | B75: 0.2376
A77: Otros productos alimenticios | B77: 0.3
A78: Chocolates para comer | B78: 0.1539
A79: Sopas secas (maggi) | B79: 0.0789507
A80: Salsa de tomate | B80: 0.040501709
A82: Bebidas alcohólicas en el hogar | B82: 0.6
A83: Cerveza | B83: 0.0738
A84: Mallorca | B84: 0.0090774
A85: Aguardiente de caña | B85: 0.0011165202
A87: Alimentos y bebidas consumidos
A88: fuera del hogar | B88: 2.3
A89: Almuerzos y comidas en restaurantes y | B89: 2.3
A90: similares
A92: VIVIENDA | B92: 19.7
A94: Alquiler | B94: 9
A95: Alquiler | B95: 9
A97: Impuesto sobre bienes raíces | B97: 0.3
A98: Impuesto sobre bienes raíces | B98: 0.3
A100: Alumbrado y combustible | B100: 4.1
...

Sheet 4.16
A1: 4.16 CANASTA DE BIENES Y SERVICIOS PARA EL CÁLCULO DEL ÍNDICE DE
A2: PRECIOS AL CONSUMIDOR - COMPONENTES Y PONDERADORES -
A3: Base: abril 1978-mayo 1979
A5: ALIMENTOS Y BEBIDAS | B5: 39.5976
A7: Cereales y derivados | B7: 6.7236
A8: Arroz | B8: 4.102
A9: Avena | B9: 0.0771
A10: Fideo | B10: 0.5667
A11: Harina de trigo | B11: 0.0685
A12: Maíz | B12: 0.0679
A13: Pan | B13: 1.8414
A15: Carnes y preparaciones | B15: 7.7533
A16: Carne de res con hueso | B16: 2.315
A17: Carne de res sin hueso | B17: 4.1049
A18: Costilla de cerdo | B18: 0.1195
... A289: Llanta y tubo | B289: 0.2403
A294: regresar al índice

Sheet 4.17
A1: 4.17 CANASTA DE BIENES Y SERVICIOS PARA EL CÁLCULO DEL ÍNDICE DE
A2: PRECIOS AL CONSUMIDOR - COMPONENTES Y PONDERADORES -
A3: Base: septiembre 1994-agosto 1995
A5: ALIMENTOS Y BEBIDAS | B5: 43.209
A7: Cereales y derivados | B7: 5.5085
A8: Arroz | B8: 2.6921
A9: Avena | B9: 0.1693
A10: Fideo | B10: 0.4443
A11: Pan | B11: 2.2028
A13: Carnes y preparaciones | B13: 7.0531
A14: Carne de res con hueso | B14: 1.7839
A15: Carne de res sin hueso | B15: 2.5879
A16: Carne de pollo | B16: 2.6813
A18: Pescados y mariscos | B18: 1.9813
A19: Pescado | B19: 1.3595
... A74: Uva | B74: 0.0772
B75: 0
A76: Frutas y vegetales en conservas | B76: 0.0224
A77: Jugo de naranja | B77: 0.0122
A78: Duraznos al jugo | B78: 0.0032
A79: Pasas | B79: 0.007
A81: Azúcar, sal y condimentos | B81: 1.6191
A82: Ajo | B82: 0.2635
A83: Azúcar | B83: 1.1201
A84: Panela | B84: 0.019
A85: Sal | B85: 0.1306
A86: Salsa de tomate | B86: 0.0859
A88: Café, te y bebidas gaseosas | B88: 1.2679
A89: Café molido | B89: 0.1171
... A286: Mantenimiento de automóvil (afinamiento, ABC) | B286: 0.2557
A291: regresar al índice

Sheet 4.18
A1: 4.18 CANASTA DE BIENES Y SERVICIOS PARA EL CÁLCULO DEL ÍNDICE DE
A2: PRECIOS AL CONSUMIDOR - COMPONENTES Y PONDERADORES -
A3: Base: enero-diciembre 2004
A5: ALIMENTOS Y BEBIDAS | B5: 32.253569
A7: Cereales y derivados | B7: 4.3121657
A8: arroz flor | B8: 1.5957175
A9: avena | B9: 0.1552767
A10: cereales preparados | B10: 0.065044
A11: fideos | B11: 0.2587467
A12: galletas | B12: 0.1302281
A13: harina de trigo | B13: 0.1000828
A14: maiz | B14: 0.0406034
A15: pan baguette | B15: 0.0630404
A16: pan corriente | B16: 1.8707432
A17: tallarines | B17: 0.0326829
... A386: neumáticos | B386: 0.2749558
A391: regresar al índice

Sheet 4.18.a
A1: 4.18.a CANASTA DE BIENES Y SERVICIOS PARA EL CÁLCULO DEL ÍNDICE DE
A2: PRECIOS AL CONSUMIDOR - COMPONENTES Y PONDERADORES -
A3: Base: enero-diciembre 2014
A5: ALIMENTOS Y BEBIDAS | B5: 30.674751
A7: Cereales y derivados | B7: 3.9444215
A8: arroz | B8: 1.5467425
A9: avena | B9: 0.078428454
A10: cereales enteros | B10: 0.049191259
A11: cereales preparados | B11: 0.095312935
A12: galletas | B12: 0.178756
A13: harina de otros cereales | B13: 0.043877345
A14: harina de trigo | B14: 0.072159826
A15: pan corriente | B15: 1.5779653
A16: pan envasado | B16: 0.053690336
A17: pan especial | B17: 0.017813257
... A446: servicio de wincha | B446: 0.034940328
A451: regresar al índice

Sheet 4.19
A1: 4.19 INDICADORES DEL MERCADO LABORAL ECUATORIANO.
A2: TOTAL NACIONAL (1) 2007-2016
A4: AÑO | B4: Tasas de
B5: Empleo Global | C5: Empleo Adecuado/Pleno | D5: Subempleo | E5: Otro Empleo No pleno | F5: Empleo No remunerado | G5: Empleo No clasificado | H5: Desempleo | I5: Desempleo Abierto | J5: Desempleo Oculto
A7: 2007 | B7: 0.95001645 | C7: 0.43199902 | D7: 0.1824284 | E7: 0.23737272 | F7: 0.087933051 | G7: 0.010283264 | H7: 0.049983546 | I7: 0.030496204 | J7: 0.019487342
A8: 2008 | B8: 0.94048537 | C8: 0.44768522 | D8: 0.15002587 | E8: 0.25829925 | F8: 0.082050636 | G8: 0.0024243977 | H8: 0.05951463 | I8: 0.03960967 | J8: 0.01990496
A9: 2009 | B9: 0.9352869 | C9: 0.39177209 | D9: 0.16363193 | E9: 0.27158275 | F9: 0.088900508 | G9: 0.019399623 | H9: 0.0647131 | I9: 0.044982826 | J9: 0.019730274
A10: 2010 | B10: 0.94981142 | C10: 0.44677099 | D10: 0.13816341 | E10: 0.27433454 | F10: 0.082189306 | G10: 0.0083531731 | H10: 0.05018858 | I10: 0.034888771 | J10: 0.015299809
A11: 2011 | B11: 0.9579454 | C11: 0.45529297 | D11: 0.107338 | E11: 0.31251796 | F11: 0.07680241 | G11: 0.0059940736 | H11: 0.042054597 | I11: 0.029806993 | J11: 0.012247605
A12: 2012 | B12: 0.95878622 | C12: 0.46532866 | D12: 0.090119229 | E12: 0.30123528 | F12: 0.080201414 | G12: 0.021901637 | H12: 0.04121378 | I12: 0.031364424 | J12: 0.0098493564
A13: 2013 | B13: 0.95847179 | C13: 0.47865018 | D13: 0.11639159 | E13: 0.29041901 | F13: 0.070930896 | G13: 0.0020801172 | H13: 0.041528209 | I13: 0.029501953 | J13: 0.012026256
A14: 2014 | B14: 0.96199694 | C14: 0.49284753 | D14: 0.12867761 | E14: 0.2675139 | F14: 0.0706755 | G14: 0.0022824096 | H14: 0.038003057 | I14: 0.030153682 | J14: 0.0078493752
A15: 2015 | B15: 0.95227165 | C15: 0.46503926 | D15: 0.14011363 | E15: 0.2642125 | F15: 0.076556542 | G15: 0.0063497184 | H15: 0.047728349 | I15: 0.036665725 | J15: 0.011062624
A16: 2016 | B16: 0.94787397 | C16: 0.411898 | D16: 0.19873267 | E16: 0.25121479 | F16: 0.083933393 | G16: 0.0020951166 | H16: 0.052126029 | I16: 0.040840831 | J16: 0.011285199
A19: 1) Datos a Diciembre de cada año
A21: regresar al índice

Sheet 4.20
A1: 4.20 INDICADORES DEL MERCADO LABORAL ECUATORIANO. (Anterior metodología)
A2: TOTAL URBANO (1) 1998-2014
A4: AÑO | B4: Tasas de
B5: Ocupación Total | C5: Ocupación Plena | D5: Subocupación Total | E5: Desocupación Total | F5: Desocupación Abierta | G5: Desocupación Oculta
A7: 1991 | B7: 0.9153287 | D7: 0.48730631 | E7: 0.084671299
A8: 1992 | B8: 0.91097498 | D8: 0.50727655 | E8: 0.089025016
A9: 1993 | B9: 0.91671485 | C9: 0.32417684 | D9: 0.50360383 | E9: 0.083285149 | F9: 0.063659289 | G9: 0.01962586
A10: 1994 | B10: 0.92868051 | C10: 0.35771873 | D10: 0.48145223 | E10: 0.071319486 | F10: 0.053829671 | G10: 0.017489815
